Workbook

Sheet Cover
A1: ISO/IEC 27001:2022 Gap Assessment
A2: Annex A Control Gap Assessment & Remediation Roadmap
A4: Client (fictional) | B4: Meridian Analytics Ltd
A5: Scope | B5: Meridian Analytics' SaaS analytics platform, corporate IT, and supporting business processes (UK head office + remote workforce)
A6: Assessment date | B6: 46266
A7: Assessor | B7: Sanika Mahamulkar
A8: Context | B8: Meridian Analytics holds ISO/IEC 27001:2013 certification. This assessment was performed ahead of the transition audit to the 2022 revision, to identify gaps against the restructured Annex A control set before the Stage 2 transition audit.
A10: Maturity Rating Legend
A11: Not Implemented (0) | B11: No control activity in place.
A12: Ad Hoc (1) | B12: Control activity occurs informally, with no defined process.
A13: Partially Implemented (2) | B13: Control is in place but incomplete, inconsistent, or not technically enforced.
A14: Implemented - Not Reviewed (3) | B14: Control is fully operating but has not yet had a formal effectiveness review.
A15: Implemented - Reviewed & Effective (4) | B15: Control is operating and has been reviewed/evidenced as effective.
A17: Priority / Remediation SLA Legend
A18: High | B18: Target remediation within 60 days of assessment date.
A19: Medium | B19: Target remediation within 120 days of assessment date.
A20: Low | B20: Target remediation within 180 days of assessment date; typically a formal-review gap rather than a true control gap.
A21: N/A - Maintain | B21: Control is mature; no remediation required, maintain and re-review periodically.
A23: Note
A24: This is a self-directed portfolio project modelling a real ISO/IEC 27001:2022 Annex A gap assessment methodology against a fictional company. All findings, maturity ratings, and dates are illustrative.

Sheet Dashboard
A1: ISO/IEC 27001:2022 Gap Assessment - Dashboard
A3: Total controls assessed | B3: =COUNTA('Gap Assessment Matrix'!A3:A95) -> 93
A4: Findings requiring action (High + Medium priority) | B4: =COUNTIFS('Gap Assessment Matrix'!G3:G95,"High")+COUNTIFS('Gap Assessment Matrix'!G3:G95,"Medium") -> 17
A5: Overall average maturity score (0-4 scale) | B5: =AVERAGE('Gap Assessment Matrix'!J3:J95) -> 3.311828
A6: Percent of controls at maturity 3 or 4 | B6: =COUNTIFS('Gap Assessment Matrix'!J3:J95,">=3")/COUNTA('Gap Assessment Matrix'!J3:J95) -> 0.8172043
A9: Controls by Theme and Maturity
A10: Theme | B10: Not Implemented | C10: Ad Hoc | D10: Partially Implemented | E10: Implemented - Not Reviewed | F10: Implemented - Reviewed & Effective
A11: Organizational | B11: =COUNTIFS('Gap Assessment Matrix'!$C$3:$C$95,$A11,'Gap Assessment Matrix'!$D$3:$D$95,B$10) -> 4 | C11: =COUNTIFS('Gap Assessment Matrix'!$C$3:$C$95,$A11,'Gap Assessment Matrix'!$D$3:$D$95,C$10) -> 0 | D11: =COUNTIFS('Gap Assessment Matrix'!$C$3:$C$95,$A11,'Gap Assessment Matrix'!$D$3:$D$95,D$10) -> 2 | E11: =COUNTIFS('Gap Assessment Matrix'!$C$3:$C$95,$A11,'Gap Assessment Matrix'!$D$3:$D$95,E$10) -> 6 | F11: =COUNTIFS('Gap Assessment Matrix'!$C$3:$C$95,$A11,'Gap Assessment Matrix'!$D$3:$D$95,F$10) -> 25
A12: People | B12: =COUNTIFS('Gap Assessment Matrix'!$C$3:$C$95,$A12,'Gap Assessment Matrix'!$D$3:$D$95,B$10) -> 0 | C12: =COUNTIFS('Gap Assessment Matrix'!$C$3:$C$95,$A12,'Gap Assessment Matrix'!$D$3:$D$95,C$10) -> 0 | D12: =COUNTIFS('Gap Assessment Matrix'!$C$3:$C$95,$A12,'Gap Assessment Matrix'!$D$3:$D$95,D$10) -> 1 | E12: =COUNTIFS('Gap Assessment Matrix'!$C$3:$C$95,$A12,'Gap Assessment Matrix'!$D$3:$D$95,E$10) -> 1 | F12: =COUNTIFS('Gap Assessment Matrix'!$C$3:$C$95,$A12,'Gap Assessment Matrix'!$D$3:$D$95,F$10) -> 6
A13: Physical | B13: =COUNTIFS('Gap Assessment Matrix'!$C$3:$C$95,$A13,'Gap Assessment Matrix'!$D$3:$D$95,B$10) -> 0 | C13: =COUNTIFS('Gap Assessment Matrix'!$C$3:$C$95,$A13,'Gap Assessment Matrix'!$D$3:$D$95,C$10) -> 0 | D13: =COUNTIFS('Gap Assessment Matrix'!$C$3:$C$95,$A13,'Gap Assessment Matrix'!$D$3:$D$95,D$10) -> 2 | E13: =COUNTIFS('Gap Assessment Matrix'!$C$3:$C$95,$A13,'Gap Assessment Matrix'!$D$3:$D$95,E$10) -> 2 | F13: =COUNTIFS('Gap Assessment Matrix'!$C$3:$C$95,$A13,'Gap Assessment Matrix'!$D$3:$D$95,F$10) -> 10
A14: Technological | B14: =COUNTIFS('Gap Assessment Matrix'!$C$3:$C$95,$A14,'Gap Assessment Matrix'!$D$3:$D$95,B$10) -> 4 | C14: =COUNTIFS('Gap Assessment Matrix'!$C$3:$C$95,$A14,'Gap Assessment Matrix'!$D$3:$D$95,C$10) -> 0 | D14: =COUNTIFS('Gap Assessment Matrix'!$C$3:$C$95,$A14,'Gap Assessment Matrix'!$D$3:$D$95,D$10) -> 4 | E14: =COUNTIFS('Gap Assessment Matrix'!$C$3:$C$95,$A14,'Gap Assessment Matrix'!$D$3:$D$95,E$10) -> 5 | F14: =COUNTIFS('Gap Assessment Matrix'!$C$3:$C$95,$A14,'Gap Assessment Matrix'!$D$3:$D$95,F$10) -> 21
A17: Findings by Priority
A18: Priority | B18: Count
A19: High | B19: =COUNTIFS('Gap Assessment Matrix'!$G$3:$G$95,A19) -> 8
A20: Medium | B20: =COUNTIFS('Gap Assessment Matrix'!$G$3:$G$95,A20) -> 9
A21: Low | B21: =COUNTIFS('Gap Assessment Matrix'!$G$3:$G$95,A21) -> 14
A22: N/A - Maintain | B22: =COUNTIFS('Gap Assessment Matrix'!$G$3:$G$95,A22) -> 62

Sheet Gap Assessment Matrix
A1: ISO/IEC 27001:2022 Annex A - Gap Assessment Matrix (93 controls)
A2: Control ID | B2: Control Name | C2: Theme | D2: Current Maturity | E2: Evidence / Notes | F2: Gap Description | G2: Priority | H2: Target Remediation Date | I2: Owner | J2: Maturity Score
A3: 5.1 | B3: Policies for information security | C3: Organizational | D3: Implemented - Reviewed & Effective | E3: Documented in the Information Security Policy Suite (v3.2); reviewed annually by the GRC team. | G3: N/A - Maintain | H3: =IF(G3="N/A - Maintain","",Cover!$B$6+INDEX('Reference Data'!$G$2:$G$5,MATCH(G3,'Reference Data'!$F$2:$F$5,0))) | I3: Head of GRC | J3: =INDEX('Reference Data'!$D$2:$D$6,MATCH(D3,'Reference Data'!$C$2:$C$6,0)) -> 4
A4: 5.2 | B4: Information security roles and responsibilities | C4: Organizational | D4: Implemented - Reviewed & Effective | E4: Process operating and evidenced via records reviewed during the last internal audit. | G4: N/A - Maintain | H4: =IF(G4="N/A - Maintain","",Cover!$B$6+INDEX('Reference Data'!$G$2:$G$5,MATCH(G4,'Reference Data'!$F$2:$F$5,0))) | I4: Head of GRC | J4: =INDEX('Reference Data'!$D$2:$D$6,MATCH(D4,'Reference Data'!$C$2:$C$6,0)) -> 4
A5: 5.3 | B5: Segregation of duties | C5: Organizational | D5: Implemented - Reviewed & Effective | E5: Control embedded in the ISMS Manual; last reviewed at the most recent management review meeting. | G5: N/A - Maintain | H5: =IF(G5="N/A - Maintain","",Cover!$B$6+INDEX('Reference Data'!$G$2:$G$5,MATCH(G5,'Reference Data'!$F$2:$F$5,0))) | I5: Head of GRC | J5: =INDEX('Reference Data'!$D$2:$D$6,MATCH(D5,'Reference Data'!$C$2:$C$6,0)) -> 4
A6: 5.4 | B6: Management responsibilities | C6: Organizational | D6: Implemented - Reviewed & Effective | E6: Evidenced via signed records retained in the document management system. | G6: N/A - Maintain | H6: =IF(G6="N/A - Maintain","",Cover!$B$6+INDEX('Reference Data'!$G$2:$G$5,MATCH(G6,'Reference Data'!$F$2:$F$5,0))) | I6: Head of GRC | J6: =INDEX('Reference Data'!$D$2:$D$6,MATCH(D6,'Reference Data'!$C$2:$C$6,0)) -> 4
A7: 5.5 | B7: Contact with authorities | C7: Organizational | D7: Implemented - Not Reviewed | E7: Documented in the Information Security Policy Suite (v3.2); reviewed annually by the GRC team. | F7: Control operating; formal review/re-attestation not yet scheduled. | G7: Low | H7: =IF(G7="N/A - Maintain","",Cover!$B$6+INDEX('Reference Data'!$G$2:$G$5,MATCH(G7,'Reference Data'!$F$2:$F$5,0))) -> 46446 | I7: Head of GRC | J7: =INDEX('Reference Data'!$D$2:$D$6,MATCH(D7,'Reference Data'!$C$2:$C$6,0)) -> 3
A8: 5.6 | B8: Contact with special interest groups | C8: Organizational | D8: Implemented - Reviewed & Effective | E8: Process operating and evidenced via records reviewed during the last internal audit. | G8: N/A - Maintain | H8: =IF(G8="N/A - Maintain","",Cover!$B$6+INDEX('Reference Data'!$G$2:$G$5,MATCH(G8,'Reference Data'!$F$2:$F$5,0))) | I8: Head of GRC | J8: =INDEX('Reference Data'!$D$2:$D$6,MATCH(D8,'Reference Data'!$C$2:$C$6,0)) -> 4
A9: 5.7 | B9: Threat intelligence | C9: Organizational | D9: Not Implemented | F9: No formal threat intelligence process; ad hoc use of vendor security bulletins only. | G9: High | H9: =IF(G9="N/A - Maintain","",Cover!$B$6+INDEX('Reference Data'!$G$2:$G$5,MATCH(G9,'Reference Data'!$F$2:$F$5,0))) -> 46326 | I9: Head of GRC | J9: =INDEX('Reference Data'!$D$2:$D$6,MATCH(D9,'Reference Data'!$C$2:$C$6,0)) -> 0
A10: 5.8 | B10: Information security in project management | C10: Organizational | D10: Implemented - Reviewed & Effective | E10: Control embedded in the ISMS Manual; last reviewed at the most recent management review meeting. | G10: N/A - Maintain | H10: =IF(G10="N/A - Maintain","",Cover!$B$6+INDEX('Reference Data'!$G$2:$G$5,MATCH(G10,'Reference Data'!$F$2:$F$5,0))) | I10: Head of GRC | J10: =INDEX('Reference Data'!$D$2:$D$6,MATCH(D10,'Reference Data'!$C$2:$C$6,0)) -> 4
A11: 5.9 | B11: Inventory of information and other associated assets | C11: Organizational | D11: Implemented - Reviewed & Effective | E11: Evidenced via signed records retained in the document management system. | G11: N/A - Maintain | H11: =IF(G11="N/A - Maintain","",Cover!$B$6+INDEX('Reference Data'!$G$2:$G$5,MATCH(G11,'Reference Data'!$F$2:$F$5,0))) | I11: Head of GRC | J11: =INDEX('Reference Data'!$D$2:$D$6,MATCH(D11,'Reference Data'!$C$2:$C$6,0)) -> 4
A12: 5.10 | B12: Acceptable use of information and other associated assets | C12: Organizational | D12: Implemented - Reviewed & Effective | E12: Documented in the Information Security Policy Suite (v3.2); reviewed annually by the GRC team. | G12: N/A - Maintain | H12: =IF(G12="N/A - Maintain","",Cover!$B$6+INDEX('Reference Data'!$G$2:$G$5,MATCH(G12,'Reference Data'!$F$2:$F$5,0))) | I12: Head of GRC | J12: =INDEX('Reference Data'!$D$2:$D$6,MATCH(D12,'Reference Data'!$C$2:$C$6,0)) -> 4
A13: 5.11 | B13: Return of assets | C13: Organizational | D13: Implemented - Not Reviewed | E13: Process operating and evidenced via records reviewed during the last internal audit. | F13: Control operating; formal review/re-attestation not yet scheduled. | G13: Low | H13: =IF(G13="N/A - Maintain","",Cover!$B$6+INDEX('Reference Data'!$G$2:$G$5,MATCH(G13,'Reference Data'!$F$2:$F$5,0))) -> 46446 | I13: Head of GRC | J13: =INDEX('Reference Data'!$D$2:$D$6,MATCH(D13,'Reference Data'!$C$2:$C$6,0)) -> 3
A14: 5.12 | B14: Classification of information | C14: Organizational | D14: Implemented - Reviewed & Effective | E14: Control embedded in the ISMS Manual; last reviewed at the most recent management review meeting. | G14: N/A - Maintain | H14: =IF(G14="N/A - Maintain","",Cover!$B$6+INDEX('Reference Data'!$G$2:$G$5,MATCH(G14,'Reference Data'!$F$2:$F$5,0))) | I14: Head of GRC | J14: =INDEX('Reference Data'!$D$2:$D$6,MATCH(D14,'Reference Data'!$C$2:$C$6,0)) -> 4
A15: 5.13 | B15: Labelling of information | C15: Organizational | D15: Implemented - Reviewed & Effective | E15: Evidenced via signed records retained in the document management system. | G15: N/A - Maintain | H15: =IF(G15="N/A - Maintain","",Cover!$B$6+INDEX('Reference Data'!$G$2:$G$5,MATCH(G15,'Reference Data'!$F$2:$F$5,0))) | I15: Head of GRC | J15: =INDEX('Reference Data'!$D$2:$D$6,MATCH(D15,'Reference Data'!$C$2:$C$6,0)) -> 4
A16: 5.14 | B16: Information transfer | C16: Organizational | D16: Implemented - Reviewed & Effective | E16: Documented in the Information Security Policy Suite (v3.2); reviewed annually by the GRC team. | G16: N/A - Maintain | H16: =IF(G16="N/A - Maintain","",Cover!$B$6+INDEX('Reference Data'!$G$2:$G$5,MATCH(G16,'Reference Data'!$F$2:$F$5,0))) | I16: Head of GRC | J16: =INDEX('Reference Data'!$D$2:$D$6,MATCH(D16,'Reference Data'!$C$2:$C$6,0)) -> 4
A17: 5.15 | B17: Access control | C17: Organizational | D17: Implemented - Reviewed & Effective | E17: Process operating and evidenced via records reviewed during the last internal audit. | G17: N/A - Maintain | H17: =IF(G17="N/A - Maintain","",Cover!$B$6+INDEX('Reference Data'!$G$2:$G$5,MATCH(G17,'Reference Data'!$F$2:$F$5,0))) | I17: Head of GRC | J17: =INDEX('Reference Data'!$D$2:$D$6,MATCH(D17,'Reference Data'!$C$2:$C$6,0)) -> 4
A18: 5.16 | B18: Identity management | C18: Organizational | D18: Implemented - Not Reviewed | E18: Control embedded in the ISMS Manual; last reviewed at the most recent management review meeting. | F18: Control operating; formal review/re-attestation not yet scheduled. | G18: Low | H18: =IF(G18="N/A - Maintain","",Cover!$B$6+INDEX('Reference Data'!$G$2:$G$5,MATCH(G18,'Reference Data'!$F$2:$F$5,0))) -> 46446 | I18: Head of GRC | J18: =INDEX('Reference Data'!$D$2:$D$6,MATCH(D18,'Reference Data'!$C$2:$C$6,0)) -> 3
A19: 5.17 | B19: Authentication information | C19: Organizational | D19: Implemented - Reviewed & Effective | E19: Evidenced via signed records retained in the document management system. | G19: N/A - Maintain | H19: =IF(G19="N/A - Maintain","",Cover!$B$6+INDEX('Reference Data'!$G$2:$G$5,MATCH(G19,'Reference Data'!$F$2:$F$5,0))) | I19: Head of GRC | J19: =INDEX('Reference Data'!$D$2:$D$6,MATCH(D19,'Reference Data'!$C$2:$C$6,0)) -> 4
A20: 5.18 | B20: Access rights | C20: Organizational | D20: Implemented - Reviewed & Effective | E20: Documented in the Information Security Policy Suite (v3.2); reviewed annually by the GRC team. | G20: N/A - Maintain | H20: =IF(G20="N/A - Maintain","",Cover!$B$6+INDEX('Reference Data'!$G$2:$G$5,MATCH(G20,'Reference Data'!$F$2:$F$5,0))) | I20: Head of GRC | J20: =INDEX('Reference Data'!$D$2:$D$6,MATCH(D20,'Reference Data'!$C$2:$C$6,0)) -> 4
A21: 5.19 | B21: Information security in supplier relationships | C21: Organizational | D21: Implemented - Reviewed & Effective | E21: Process operating and evidenced via records reviewed during the last internal audit. | G21: N/A - Maintain | H21: =IF(G21="N/A - Maintain","",Cover!$B$6+INDEX('Reference Data'!$G$2:$G$5,MATCH(G21,'Reference Data'!$F$2:$F$5,0))) | I21: Vendor & Procurement Manager | J21: =INDEX('Reference Data'!$D$2:$D$6,MATCH(D21,'Reference Data'!$C$2:$C$6,0)) -> 4
A22: 5.20 | B22: Addressing information security within supplier agreements | C22: Organizational | D22: Implemented - Reviewed & Effective | E22: Control embedded in the ISMS Manual; last reviewed at the most recent management review meeting. | G22: N/A - Maintain | H22: =IF(G22="N/A - Maintain","",Cover!$B$6+INDEX('Reference Data'!$G$2:$G$5,MATCH(G22,'Reference Data'!$F$2:$F$5,0))) | I22: Vendor & Procurement Manager | J22: =INDEX('Reference Data'!$D$2:$D$6,MATCH(D22,'Reference Data'!$C$2:$C$6,0)) -> 4
A23: 5.21 | B23: Managing information security in the ICT supply chain | C23: Organizational | D23: Not Implemented | F23: ICT supply chain risk is not assessed separately from general supplier due diligence. | G23: High | H23: =IF(G23="N/A - Maintain","",Cover!$B$6+INDEX('Reference Data'!$G$2:$G$5,MATCH(G23,'Reference Data'!$F$2:$F$5,0))) -> 46326 | I23: Vendor & Procurement Manager | J23: =INDEX('Reference Data'!$D$2:$D$6,MATCH(D23,'Reference Data'!$C$2:$C$6,0)) -> 0
A24: 5.22 | B24: Monitoring, review, and change management of supplier services | C24: Organizational | D24: Implemented - Not Reviewed | E24: Evidenced via signed records retained in the document management system. | F24: Control operating; formal review/re-attestation not yet scheduled. | G24: Low | H24: =IF(G24="N/A - Maintain","",Cover!$B$6+INDEX('Reference Data'!$G$2:$G$5,MATCH(G24,'Reference Data'!$F$2:$F$5,0))) -> 46446 | I24: Vendor & Procurement Manager | J24: =INDEX('Reference Data'!$D$2:$D$6,MATCH(D24,'Reference Data'!$C$2:$C$6,0)) -> 3
A25: 5.23 | B25: Information security for use of cloud services | C25: Organizational | D25: Partially Implemented | F25: Cloud vendor security is reviewed at onboarding only; no ongoing cloud security governance process. | G25: Medium | H25: =IF(G25="N/A - Maintain","",Cover!$B$6+INDEX('Reference Data'!$G$2:$G$5,MATCH(G25,'Reference Data'!$F$2:$F$5,0))) -> 46386 | I25: Head of GRC | J25: =INDEX('Reference Data'!$D$2:$D$6,MATCH(D25,'Reference Data'!$C$2:$C$6,0)) -> 2
A26: 5.24 | B26: Information security incident management planning and preparation | C26: Organizational | D26: Implemented - Reviewed & Effective | E26: Documented in the Information Security Policy Suite (v3.2); reviewed annually by the GRC team. | G26: N/A - Maintain | H26: =IF(G26="N/A - Maintain","",Cover!$B$6+INDEX('Reference Data'!$G$2:$G$5,MATCH(G26,'Reference Data'!$F$2:$F$5,0))) | I26: Security Operations Lead | J26: =INDEX('Reference Data'!$D$2:$D$6,MATCH(D26,'Reference Data'!$C$2:$C$6,0)) -> 4
A27: 5.25 | B27: Assessment and decision on information security events | C27: Organizational | D27: Implemented - Reviewed & Effective | E27: Process operating and evidenced via records reviewed during the last internal audit. | G27: N/A - Maintain | H27: =IF(G27="N/A - Maintain","",Cover!$B$6+INDEX('Reference Data'!$G$2:$G$5,MATCH(G27,'Reference Data'!$F$2:$F$5,0))) | I27: Security Operations Lead | J27: =INDEX('Reference Data'!$D$2:$D$6,MATCH(D27,'Reference Data'!$C$2:$C$6,0)) -> 4
A28: 5.26 | B28: Response to information security incidents | C28: Organizational | D28: Implemented - Reviewed & Effective | E28: Control embedded in the ISMS Manual; last reviewed at the most recent management review meeting. | G28: N/A - Maintain | H28: =IF(G28="N/A - Maintain","",Cover!$B$6+INDEX('Reference Data'!$G$2:$G$5,MATCH(G28,'Reference Data'!$F$2:$F$5,0))) | I28: Security Operations Lead | J28: =INDEX('Reference Data'!$D$2:$D$6,MATCH(D28,'Reference Data'!$C$2:$C$6,0)) -> 4
A29: 5.27 | B29: Learning from information security incidents | C29: Organizational | D29: Implemented - Reviewed & Effective | E29: Evidenced via signed records retained in the document management system. | G29: N/A - Maintain | H29: =IF(G29="N/A - Maintain","",Cover!$B$6+INDEX('Reference Data'!$G$2:$G$5,MATCH(G29,'Reference Data'!$F$2:$F$5,0))) | I29: Security Operations Lead | J29: =INDEX('Reference Data'!$D$2:$D$6,MATCH(D29,'Reference Data'!$C$2:$C$6,0)) -> 4
A30: 5.28 | B30: Collection of evidence | C30: Organizational | D30: Not Implemented | F30: No documented procedure for collection and preservation of evidence following a security incident. | G30: High | H30: =IF(G30="N/A - Maintain","",Cover!$B$6+INDEX('Reference Data'!$G$2:$G$5,MATCH(G30,'Reference Data'!$F$2:$F$5,0))) -> 46326 | I30: Security Operations Lead | J30: =INDEX('Reference Data'!$D$2:$D$6,MATCH(D30,'Reference Data'!$C$2:$C$6,0)) -> 0
A31: 5.29 | B31: Information security during disruption | C31: Organizational | D31: Implemented - Not Reviewed | E31: Documented in the Information Security Policy Suite (v3.2); reviewed annually by the GRC team. | F31: Control operating; formal review/re-attestation not yet scheduled. | G31: Low | H31: =IF(G31="N/A - Maintain","",Cover!$B$6+INDEX('Reference Data'!$G$2:$G$5,MATCH(G31,'Reference Data'!$F$2:$F$5,0))) -> 46446 | I31: Head of GRC | J31: =INDEX('Reference Data'!$D$2:$D$6,MATCH(D31,'Reference Data'!$C$2:$C$6,0)) -> 3
A32: 5.30 | B32: ICT readiness for business continuity | C32: Organizational | D32: Not Implemented | F32: ICT continuity plan not yet aligned to BIA-derived recovery time/point objectives. | G32: High | H32: =IF(G32="N/A - Maintain","",Cover!$B$6+INDEX('Reference Data'!$G$2:$G$5,MATCH(G32,'Reference Data'!$F$2:$F$5,0))) -> 46326 | I32: Head of GRC | J32: =INDEX('Reference Data'!$D$2:$D$6,MATCH(D32,'Reference Data'!$C$2:$C$6,0)) -> 0
A33: 5.31 | B33: Legal, statutory, regulatory, and contractual requirements | C33: Organizational | D33: Implemented - Reviewed & Effective | E33: Process operating and evidenced via records reviewed during the last internal audit. | G33: N/A - Maintain | H33: =IF(G33="N/A - Maintain","",Cover!$B$6+INDEX('Reference Data'!$G$2:$G$5,MATCH(G33,'Reference Data'!$F$2:$F$5,0))) | I33: Data Protection Officer | J33: =INDEX('Reference Data'!$D$2:$D$6,MATCH(D33,'Reference Data'!$C$2:$C$6,0)) -> 4
A34: 5.32 | B34: Intellectual property rights | C34: Organizational | D34: Implemented - Reviewed & Effective | E34: Control embedded in the ISMS Manual; last reviewed at the most recent management review meeting. | G34: N/A - Maintain | H34: =IF(G34="N/A - Maintain","",Cover!$B$6+INDEX('Reference Data'!$G$2:$G$5,MATCH(G34,'Reference Data'!$F$2:$F$5,0))) | I34: Legal Counsel | J34: =INDEX('Reference Data'!$D$2:$D$6,MATCH(D34,'Reference Data'!$C$2:$C$6,0)) -> 4
A35: 5.33 | B35: Protection of records | C35: Organizational | D35: Implemented - Reviewed & Effective | E35: Evidenced via signed records retained in the document management system. | G35: N/A - Maintain | H35: =IF(G35="N/A - Maintain","",Cover!$B$6+INDEX('Reference Data'!$G$2:$G$5,MATCH(G35,'Reference Data'!$F$2:$F$5,0))) | I35: Data Protection Officer | J35: =INDEX('Reference Data'!$D$2:$D$6,MATCH(D35,'Reference Data'!$C$2:$C$6,0)) -> 4
A36: 5.34 | B36: Privacy and protection of PII | C36: Organizational | D36: Implemented - Reviewed & Effective | E36: Documented in the Information Security Policy Suite (v3.2); reviewed annually by the GRC team. | G36: N/A - Maintain | H36: =IF(G36="N/A - Maintain","",Cover!$B$6+INDEX('Reference Data'!$G$2:$G$5,MATCH(G36,'Reference Data'!$F$2:$F$5,0))) | I36: Data Protection Officer | J36: =INDEX('Reference Data'!$D$2:$D$6,MATCH(D36,'Reference Data'!$C$2:$C$6,0)) -> 4
A37: 5.35 | B37: Independent review of information security | C37: Organizational | D37: Partially Implemented | F37: Last independent ISMS review was 19 months ago; no fixed review cadence is defined. | G37: Medium | H37: =IF(G37="N/A - Maintain","",Cover!$B$6+INDEX('Reference Data'!$G$2:$G$5,MATCH(G37,'Reference Data'!$F$2:$F$5,0))) -> 46386 | I37: Head of GRC | J37: =INDEX('Reference Data'!$D$2:$D$6,MATCH(D37,'Reference Data'!$C$2:$C$6,0)) -> 2
A38: 5.36 | B38: Compliance with policies, rules, and standards | C38: Organizational | D38: Implemented - Not Reviewed | E38: Process operating and evidenced via records reviewed during the last internal audit. | F38: Control operating; formal review/re-attestation not yet scheduled. | G38: Low | H38: =IF(G38="N/A - Maintain","",Cover!$B$6+INDEX('Reference Data'!$G$2:$G$5,MATCH(G38,'Reference Data'!$F$2:$F$5,0))) -> 46446 | I38: Head of GRC | J38: =INDEX('Reference Data'!$D$2:$D$6,MATCH(D38,'Reference Data'!$C$2:$C$6,0)) -> 3
A39: 5.37 | B39: Documented operating procedures | C39: Organizational | D39: Implemented - Reviewed & Effective | E39: Control embedded in the ISMS Manual; last reviewed at the most recent management review meeting. | G39: N/A - Maintain | H39: =IF(G39="N/A - Maintain","",Cover!$B$6+INDEX('Reference Data'!$G$2:$G$5,MATCH(G39,'Reference Data'!$F$2:$F$5,0))) | I39: Head of GRC | J39: =INDEX('Reference Data'!$D$2:$D$6,MATCH(D39,'Reference Data'!$C$2:$C$6,0)) -> 4
A40: 6.1 | B40: Screening | C40: People | D40: Implemented - Reviewed & Effective | E40: Evidenced via HR onboarding/offboarding checklist completion records. | G40: N/A - Maintain | H40: =IF(G40="N/A - Maintain","",Cover!$B$6+INDEX('Reference Data'!$G$2:$G$5,MATCH(G40,'Reference Data'!$F$2:$F$5,0))) | I40: HR Director | J40: =INDEX('Reference Data'!$D$2:$D$6,MATCH(D40,'Reference Data'!$C$2:$C$6,0)) -> 4
...

Sheet Remediation Roadmap
A1: Remediation Roadmap - Findings Requiring Action
A2: Control ID | B2: Control Name | C2: Gap Description | D2: Priority | E2: Owner | F2: Target Remediation Date | G2: Status
A3: ='Gap Assessment Matrix'!A23 -> 5.21 | B3: ='Gap Assessment Matrix'!B23 -> Managing information security in the ICT supply chain | C3: ='Gap Assessment Matrix'!F23 -> ICT supply chain risk is not assessed separately from general supplier due diligence. | D3: ='Gap Assessment Matrix'!G23 -> High | E3: ='Gap Assessment Matrix'!I23 -> Vendor & Procurement Manager | F3: ='Gap Assessment Matrix'!H23 -> 46326 | G3: Not Started
A4: ='Gap Assessment Matrix'!A30 -> 5.28 | B4: ='Gap Assessment Matrix'!B30 -> Collection of evidence | C4: ='Gap Assessment Matrix'!F30 -> No documented procedure for collection and preservation of evidence following a security incident. | D4: ='Gap Assessment Matrix'!G30 -> High | E4: ='Gap Assessment Matrix'!I30 -> Security Operations Lead | F4: ='Gap Assessment Matrix'!H30 -> 46326 | G4: Not Started
A5: ='Gap Assessment Matrix'!A32 -> 5.30 | B5: ='Gap Assessment Matrix'!B32 -> ICT readiness for business continuity | C5: ='Gap Assessment Matrix'!F32 -> ICT continuity plan not yet aligned to BIA-derived recovery time/point objectives. | D5: ='Gap Assessment Matrix'!G32 -> High | E5: ='Gap Assessment Matrix'!I32 -> Head of GRC | F5: ='Gap Assessment Matrix'!H32 -> 46326 | G5: Not Started
A6: ='Gap Assessment Matrix'!A9 -> 5.7 | B6: ='Gap Assessment Matrix'!B9 -> Threat intelligence | C6: ='Gap Assessment Matrix'!F9 -> No formal threat intelligence process; ad hoc use of vendor security bulletins only. | D6: ='Gap Assessment Matrix'!G9 -> High | E6: ='Gap Assessment Matrix'!I9 -> Head of GRC | F6: ='Gap Assessment Matrix'!H9 -> 46326 | G6: Not Started
A7: ='Gap Assessment Matrix'!A72 -> 8.11 | B7: ='Gap Assessment Matrix'!B72 -> Data masking | C7: ='Gap Assessment Matrix'!F72 -> No data masking applied to production data copied into test/staging environments. | D7: ='Gap Assessment Matrix'!G72 -> High | E7: ='Gap Assessment Matrix'!I72 -> IT Security Manager | F7: ='Gap Assessment Matrix'!H72 -> 46326 | G7: Not Started
A8: ='Gap Assessment Matrix'!A73 -> 8.12 | B8: ='Gap Assessment Matrix'!B73 -> Data leakage prevention | C8: ='Gap Assessment Matrix'!F73 -> No data leakage prevention tooling in place; reliance on manual review and the acceptable use policy only. | D8: ='Gap Assessment Matrix'!G73 -> High | E8: ='Gap Assessment Matrix'!I73 -> IT Security Manager | F8: ='Gap Assessment Matrix'!H73 -> 46326 | G8: Not Started
A9: ='Gap Assessment Matrix'!A77 -> 8.16 | B9: ='Gap Assessment Matrix'!B77 -> Monitoring activities | C9: ='Gap Assessment Matrix'!F77 -> No centralised security monitoring/SIEM capability; log review is manual and inconsistent. | D9: ='Gap Assessment Matrix'!G77 -> High | E9: ='Gap Assessment Matrix'!I77 -> IT Security Manager | F9: ='Gap Assessment Matrix'!H77 -> 46326 | G9: Not Started
A10: ='Gap Assessment Matrix'!A70 -> 8.9 | B10: ='Gap Assessment Matrix'!B70 -> Configuration management | C10: ='Gap Assessment Matrix'!F70 -> No formal secure baseline configuration standard; configurations vary by engineer. | D10: ='Gap Assessment Matrix'!G70 -> High | E10: ='Gap Assessment Matrix'!I70 -> IT Security Manager | F10: ='Gap Assessment Matrix'!H70 -> 46326 | G10: Not Started
A11: ='Gap Assessment Matrix'!A25 -> 5.23 | B11: ='Gap Assessment Matrix'!B25 -> Information security for use of cloud services | C11: ='Gap Assessment Matrix'!F25 -> Cloud vendor security is reviewed at onboarding only; no ongoing cloud security governance process. | D11: ='Gap Assessment Matrix'!G25 -> Medium | E11: ='Gap Assessment Matrix'!I25 -> Head of GRC | F11: ='Gap Assessment Matrix'!H25 -> 46386 | G11: Not Started
A12: ='Gap Assessment Matrix'!A37 -> 5.35 | B12: ='Gap Assessment Matrix'!B37 -> Independent review of information security | C12: ='Gap Assessment Matrix'!F37 -> Last independent ISMS review was 19 months ago; no fixed review cadence is defined. | D12: ='Gap Assessment Matrix'!G37 -> Medium | E12: ='Gap Assessment Matrix'!I37 -> Head of GRC | F12: ='Gap Assessment Matrix'!H37 -> 46386 | G12: Not Started
A13: ='Gap Assessment Matrix'!A46 -> 6.7 | B13: ='Gap Assessment Matrix'!B46 -> Remote working | C13: ='Gap Assessment Matrix'!F46 -> Remote working policy exists but is not technically enforced (e.g. no device posture check). | D13: ='Gap Assessment Matrix'!G46 -> Medium | E13: ='Gap Assessment Matrix'!I46 -> HR Director | F13: ='Gap Assessment Matrix'!H46 -> 46386 | G13: Not Started
A14: ='Gap Assessment Matrix'!A51 -> 7.4 | B14: ='Gap Assessment Matrix'!B51 -> Physical security monitoring | C14: ='Gap Assessment Matrix'!F51 -> CCTV covers the main entrance only; the server room and other secure areas are not monitored. | D14: ='Gap Assessment Matrix'!G51 -> Medium | E14: ='Gap Assessment Matrix'!I51 -> Facilities Manager | F14: ='Gap Assessment Matrix'!H51 -> 46386 | G14: Not Started
A15: ='Gap Assessment Matrix'!A56 -> 7.9 | B15: ='Gap Assessment Matrix'!B56 -> Security of assets off-premises | C15: ='Gap Assessment Matrix'!F56 -> No formal register of assets used off-premises; reliant on employee self-reporting. | D15: ='Gap Assessment Matrix'!G56 -> Medium | E15: ='Gap Assessment Matrix'!I56 -> Facilities Manager | F15: ='Gap Assessment Matrix'!H56 -> 46386 | G15: Not Started
A16: ='Gap Assessment Matrix'!A71 -> 8.10 | B16: ='Gap Assessment Matrix'!B71 -> Information deletion | C16: ='Gap Assessment Matrix'!F71 -> Deletion occurs on request (e.g. DSAR) but there is no scheduled deletion against the retention schedule. | D16: ='Gap Assessment Matrix'!G71 -> Medium | E16: ='Gap Assessment Matrix'!I71 -> IT Security Manager | F16: ='Gap Assessment Matrix'!H71 -> 46386 | G16: Not Started
A17: ='Gap Assessment Matrix'!A84 -> 8.23 | B17: ='Gap Assessment Matrix'!B84 -> Web filtering | C17: ='Gap Assessment Matrix'!F84 -> Web filtering is enabled for malware categories only; no policy-based category filtering. | D17: ='Gap Assessment Matrix'!G84 -> Medium | E17: ='Gap Assessment Matrix'!I84 -> IT Security Manager | F17: ='Gap Assessment Matrix'!H84 -> 46386 | G17: Not Started
A18: ='Gap Assessment Matrix'!A89 -> 8.28 | B18: ='Gap Assessment Matrix'!B89 -> Secure coding | C18: ='Gap Assessment Matrix'!F89 -> Secure coding guidelines exist but are not enforced via automated code review or linting. | D18: ='Gap Assessment Matrix'!G89 -> Medium | E18: ='Gap Assessment Matrix'!I89 -> Head of Engineering | F18: ='Gap Assessment Matrix'!H89 -> 46386 | G18: Not Started
A19: ='Gap Assessment Matrix'!A69 -> 8.8 | B19: ='Gap Assessment Matrix'!B69 -> Management of technical vulnerabilities | C19: ='Gap Assessment Matrix'!F69 -> Vulnerability scanning is performed quarterly; no formal SLA for remediation by severity. | D19: ='Gap Assessment Matrix'!G69 -> Medium | E19: ='Gap Assessment Matrix'!I69 -> IT Security Manager | F19: ='Gap Assessment Matrix'!H69 -> 46386 | G19: Not Started

Sheet Reference Data
A1: Maturity Label | B1: (unused) | C1: Maturity Label | D1: Score | F1: Priority | G1: Remediation Days
C2: Not Implemented | D2: 0 | F2: High | G2: 60
C3: Ad Hoc | D3: 1 | F3: Medium | G3: 120
C4: Partially Implemented | D4: 2 | F4: Low | G4: 180
C5: Implemented - Not Reviewed | D5: 3 | F5: N/A - Maintain
C6: Implemented - Reviewed & Effective | D6: 4
